Workbook

Sheet Database
A1: Order ID | B1: Date | C1: Month | D1: Product | E1: Category | F1: Quantity | G1: Unit Price (SAR) | H1: Total (SAR) | I1: Payment Method | J1: Employee
A2: ORD-1001 | B2: 46208 | C2: =TEXT(B2,"mmm yyyy") -> Jul 2026 | D2: Tissue Box | E2: Household | F2: 3 | G2: 9 | H2: =F2*G2 -> 27 | I2: Mada | J2: Noura
A3: ORD-1002 | B3: 46209 | C3: =TEXT(B3,"mmm yyyy") -> Jul 2026 | D3: Fresh Milk 1L | E3: Dairy | F3: 1 | G3: 7 | H3: =F3*G3 -> 7 | I3: Cash | J3: Khalid
A4: ORD-1003 | B4: 46210 | C4: =TEXT(B4,"mmm yyyy") -> Jul 2026 | D4: Salted Nuts | E4: Snacks | F4: 6 | G4: 12 | H4: =F4*G4 -> 72 | I4: Credit Card | J4: Noura
A5: ORD-1004 | B5: 46210 | C5: =TEXT(B5,"mmm yyyy") -> Jul 2026 | D5: Toast Bread | E5: Bakery | F5: 4 | G5: 5.5 | H5: =F5*G5 -> 22 | I5: Cash | J5: Ahmed
A6: ORD-1005 | B6: 46211 | C6: =TEXT(B6,"mmm yyyy") -> Jul 2026 | D6: Chocolate Bar | E6: Snacks | F6: 4 | G6: 4.5 | H6: =F6*G6 -> 18 | I6: Cash | J6: Ahmed
A7: ORD-1006 | B7: 46211 | C7: =TEXT(B7,"mmm yyyy") -> Jul 2026 | D7: Dish Soap | E7: Household | F7: 6 | G7: 11 | H7: =F7*G7 -> 66 | I7: Credit Card | J7: Noura
A8: ORD-1007 | B8: 46211 | C8: =TEXT(B8,"mmm yyyy") -> Jul 2026 | D8: Chocolate Bar | E8: Snacks | F8: 6 | G8: 4.5 | H8: =F8*G8 -> 27 | I8: Apple Pay | J8: Khalid
A9: ORD-1008 | B9: 46211 | C9: =TEXT(B9,"mmm yyyy") -> Jul 2026 | D9: Mineral Water 1.5L | E9: Beverages | F9: 4 | G9: 2.5 | H9: =F9*G9 -> 10 | I9: Credit Card | J9: Sara
A10: ORD-1009 | B10: 46212 | C10: =TEXT(B10,"mmm yyyy") -> Jul 2026 | D10: Toast Bread | E10: Bakery | F10: 1 | G10: 5.5 | H10: =F10*G10 -> 5.5 | I10: Apple Pay | J10: Ahmed
A11: ORD-1010 | B11: 46212 | C11: =TEXT(B11,"mmm yyyy") -> Jul 2026 | D11: Potato Chips | E11: Snacks | F11: 3 | G11: 6 | H11: =F11*G11 -> 18 | I11: Mada | J11: Sara
A12: ORD-1011 | B12: 46213 | C12: =TEXT(B12,"mmm yyyy") -> Jul 2026 | D12: Fresh Milk 1L | E12: Dairy | F12: 4 | G12: 7 | H12: =F12*G12 -> 28 | I12: Apple Pay | J12: Ahmed
A13: ORD-1012 | B13: 46213 | C13: =TEXT(B13,"mmm yyyy") -> Jul 2026 | D13: Cola 330ml | E13: Beverages | F13: 4 | G13: 3 | H13: =F13*G13 -> 12 | I13: Apple Pay | J13: Khalid
... A91: ORD-1090 | B91: 46295 | C91: =TEXT(B91,"mmm yyyy") -> Sep 2026 | D91: Fresh Milk 1L | E91: Dairy | F91: 1 | G91: 7 | H91: =F91*G91 -> 7 | I91: Credit Card | J91: Ahmed

Sheet Data_Source
A1: Order ID | B1: DATE | C1: MONTH | D1: PRODUCT | E1: CATEGORY | F1: QUANTITY | G1: UNIT PRICE (SAR) | H1: TOTAL(SAR) | I1: PAYMENT METHOD | J1: EMPLOYEE
A2: ORD-1001 | B2: 46208 | C2: =TEXT(B2,"mmm yyyy") -> Jul 2026 | D2: Tissue Box | E2: Household | F2: 3 | G2: 9 | H2: =F2*G2 -> 27 | I2: Mada | J2: Noura
A3: ORD-1002 | B3: 46209 | C3: =TEXT(B3,"mmm yyyy") -> Jul 2026 | D3: Fresh Milk 1L | E3: Dairy | F3: 1 | G3: 7 | H3: =F3*G3 -> 7 | I3: Cash | J3: Khalid
A4: ORD-1003 | B4: 46210 | C4: =TEXT(B4,"mmm yyyy") -> Jul 2026 | D4: Salted Nuts | E4: Snacks | F4: 6 | G4: 12 | H4: =F4*G4 -> 72 | I4: Credit Card | J4: Noura
A5: ORD-1004 | B5: 46210 | C5: =TEXT(B5,"mmm yyyy") -> Jul 2026 | D5: Toast Bread | E5: Bakery | F5: 4 | G5: 5.5 | H5: =F5*G5 -> 22 | I5: Cash | J5: Ahmed
A6: ORD-1005 | B6: 46211 | C6: =TEXT(B6,"mmm yyyy") -> Jul 2026 | D6: Chocolate Bar | E6: Snacks | F6: 4 | G6: 4.5 | H6: =F6*G6 -> 18 | I6: Cash | J6: Ahmed
A7: ORD-1006 | B7: 46211 | C7: =TEXT(B7,"mmm yyyy") -> Jul 2026 | D7: Dish Soap | E7: Household | F7: 6 | G7: 11 | H7: =F7*G7 -> 66 | I7: Credit Card | J7: Noura
A8: ORD-1007 | B8: 46211 | C8: =TEXT(B8,"mmm yyyy") -> Jul 2026 | D8: Chocolate Bar | E8: Snacks | F8: 6 | G8: 4.5 | H8: =F8*G8 -> 27 | I8: Apple Pay | J8: Khalid
A9: ORD-1008 | B9: 46211 | C9: =TEXT(B9,"mmm yyyy") -> Jul 2026 | D9: Mineral Water 1.5L | E9: Beverages | F9: 4 | G9: 2.5 | H9: =F9*G9 -> 10 | I9: Credit Card | J9: Sara
A10: ORD-1009 | B10: 46212 | C10: =TEXT(B10,"mmm yyyy") -> Jul 2026 | D10: Toast Bread | E10: Bakery | F10: 1 | G10: 5.5 | H10: =F10*G10 -> 5.5 | I10: Apple Pay | J10: Ahmed
A11: ORD-1010 | B11: 46212 | C11: =TEXT(B11,"mmm yyyy") -> Jul 2026 | D11: Potato Chips | E11: Snacks | F11: 3 | G11: 6 | H11: =F11*G11 -> 18 | I11: Mada | J11: Sara
A12: ORD-1011 | B12: 46213 | C12: =TEXT(B12,"mmm yyyy") -> Jul 2026 | D12: Fresh Milk 1L | E12: Dairy | F12: 4 | G12: 7 | H12: =F12*G12 -> 28 | I12: Apple Pay | J12: Ahmed
A13: ORD-1012 | B13: 46213 | C13: =TEXT(B13,"mmm yyyy") -> Jul 2026 | D13: Cola 330ml | E13: Beverages | F13: 4 | G13: 3 | H13: =F13*G13 -> 12 | I13: Apple Pay | J13: Khalid
... A91: ORD-1090 | B91: 46295 | C91: =TEXT(B91,"mmm yyyy") -> Sep 2026 | D91: Fresh Milk 1L | E91: Dairy | F91: 1 | G91: 7 | H91: =F91*G91 -> 7 | I91: Credit Card | J91: Ahmed

Sheet Pivot Tables
A3: Total Quantity | B3: Months
A4: Product Name | B4: Jul 2026 | C4: Aug 2026 | D4: Sep 2026 | E4: Grand Total
A5: Cheese Slices | B5: 3 | C5: 5 | D5: 16 | E5: 24
A6: Chocolate Bar | B6: 11 | C6: 2 | D6: 7 | E6: 20
A7: Cola 330ml | B7: 9 | C7: 15 | D7: 8 | E7: 32
A8: Croissant | B8: 7 | C8: 9 | D8: 2 | E8: 18
A9: Dish Soap | B9: 14 | D9: 14 | E9: 28
A10: Fresh Milk 1L | B10: 9 | C10: 20 | D10: 9 | E10: 38
A11: Mineral Water 1.5L | B11: 9 | C11: 4 | E11: 13
A12: Orange Juice 1L | B12: 7 | C12: 2 | D12: 11 | E12: 20
A13: Potato Chips | B13: 14 | C13: 6 | D13: 9 | E13: 29
A14: Salted Nuts | B14: 17 | D14: 5 | E14: 22
A15: Tissue Box | B15: 9 | C15: 12 | D15: 8 | E15: 29
A16: Toast Bread | B16: 5 | C16: 4 | E16: 9
A17: Yogurt 500g | B17: 10 | C17: 7 | D17: 12 | E17: 29
A18: Grand Total | B18: 124 | C18: 86 | D18: 101 | E18: 311
A27: Row Labels | B27: Sum of TOTAL(SAR)
A28: Bakery | B28: 112.5
A29: Croissant | B29: 63
A30: Toast Bread | B30: 49.5
A31: Beverages | B31: 288.5
A32: Cola 330ml | B32: 96
A33: Mineral Water 1.5L | B33: 32.5
A34: Orange Juice 1L | B34: 160
A35: Dairy | B35: 747
A36: Cheese Slices | B36: 336
A37: Fresh Milk 1L | B37: 266
A38: Yogurt 500g | B38: 145
A39: Household | B39: 569
... A46: Grand Total | B46: 2245
A51: Sum of QUANTITY | B51: Column Labels
A52: Row Labels | B52: Cheese Slices | C52: Chocolate Bar | D52: Cola 330ml | E52: Croissant | F52: Dish Soap | G52: Fresh Milk 1L | H52: Mineral Water 1.5L | I52: Orange Juice 1L | J52: Potato Chips | K52: Salted Nuts | L52: Tissue Box | M52: Toast Bread | N52: Yogurt 500g | O52: Grand Total
A53: Ahmed | B53: 19 | C53: 4 | D53: 6 | E53: 5 | G53: 11 | H53: 5 | I53: 11 | J53: 15 | K53: 5 | M53: 5 | N53: 2 | O53: 88
A54: Khalid | B54: 1 | C54: 8 | D54: 13 | E54: 4 | F54: 5 | G54: 5 | H54: 3 | I54: 2 | L54: 11 | N54: 12 | O54: 64
A55: Noura | B55: 1 | C55: 1 | D55: 4 | F55: 15 | G55: 10 | J55: 6 | K55: 11 | L55: 15 | M55: 4 | N55: 6 | O55: 73
A56: Sara | B56: 3 | C56: 7 | D56: 9 | E56: 9 | F56: 8 | G56: 12 | H56: 5 | I56: 7 | J56: 8 | K56: 6 | L56: 3 | N56: 9 | O56: 86
A57: Grand Total | B57: 24 | C57: 20 | D57: 32 | E57: 18 | F57: 28 | G57: 38 | H57: 13 | I57: 20 | J57: 29 | K57: 22 | L57: 29 | M57: 9 | N57: 29 | O57: 311
A62: Employee Names | B62: Grand Total | C62: RANK
A63: Ahmed | B63: =O53 -> 88 | C63: =RANK(B63,$B$63:$B$66) -> 1
A64: Khalid | B64: =O54 -> 64 | C64: =RANK(B64,$B$63:$B$66) -> 4
...

Sheet Dashboard
A1: Total Sales (SAR) | D1: Number of Orders | G1: Units Sold | J1: Average Order Value (SAR)
A2: =SUM(Database!$H$2:$H$91) -> 2245 | D2: =COUNTA(Database!$A$2:$A$91) -> 90 | G2: =SUM(Database!$F$2:$F$91) -> 311 | J2: =A2/D2 -> 24.944444
